#### try catch 문
```java
package chapter14;

public class Exception2 {
    public static void main(String[] args) {
        //다중 예외 처리 (다중 cathch)
        
        try {
        int[] arr = {10, 20, 30};
            //ArrayIndexOutOfBoundsException
            System.out.println(arr[5]);
            
            //ArithmeticException
            System.out.println(3 / 0);
            
            //NumberFormatException
            Integer.parseInt("a");
        } catch (ArrayIndexOutOfBoundsException e) {
            System.out.println(e.getMessage());
        } catch (ArithmeticException e) {
            System.out.println(e.getMessage());
        } catch (NumberFormatException e) {
            System.out.println(e.getMessage());
        } catch (Exception e) {
            System.out.println(e.getMessage());
        } finally {
            System.out.println("예외와 상관없이 항상 수행되는 구문");
        }
                
        
        try {
            int[] arr1 = {1, 2, 3};
            System.out.println(arr1[5]);
            System.out.println(3 / 0);
            Integer.parseInt("a");
        } catch (ArrayIndexOutOfBoundsException | ArithmeticException | NumberFormatException | Exception e) {
            
        }        
    }


}

```